2018-03-26 00:18:52,338 ERROR: Exception on /reset_password_request [POST] [in /home/ronnie/.local/share/virtualenvs/microblog-_cc4o7Cx/lib/python3.5/site-packages/flask/app.py:1560]
Traceback (most recent call last):
  File "/home/ronnie/.local/share/virtualenvs/microblog-_cc4o7Cx/lib/python3.5/site-packages/flask/app.py", line 1982, in wsgi_app
    response = self.full_dispatch_request()
  File "/home/ronnie/.local/share/virtualenvs/microblog-_cc4o7Cx/lib/python3.5/site-packages/flask/app.py", line 1614, in full_dispatch_request
    rv = self.handle_user_exception(e)
  File "/home/ronnie/.local/share/virtualenvs/microblog-_cc4o7Cx/lib/python3.5/site-packages/flask/app.py", line 1517, in handle_user_exception
    reraise(exc_type, exc_value, tb)
  File "/home/ronnie/.local/share/virtualenvs/microblog-_cc4o7Cx/lib/python3.5/site-packages/flask/_compat.py", line 33, in reraise
    raise value
  File "/home/ronnie/.local/share/virtualenvs/microblog-_cc4o7Cx/lib/python3.5/site-packages/flask/app.py", line 1612, in full_dispatch_request
    rv = self.dispatch_request()
  File "/home/ronnie/.local/share/virtualenvs/microblog-_cc4o7Cx/lib/python3.5/site-packages/flask/app.py", line 1598, in dispatch_request
    return self.view_functions[rule.endpoint](**req.view_args)
  File "/home/ronnie/coding/microblog/app/routes.py", line 155, in reset_password_request
    send_password_reset_email(user)
  File "/home/ronnie/coding/microblog/app/email.py", line 18, in send_password_reset_email
    user=user, token=token),
  File "/home/ronnie/.local/share/virtualenvs/microblog-_cc4o7Cx/lib/python3.5/site-packages/flask/templating.py", line 133, in render_template
    return _render(ctx.app.jinja_env.get_or_select_template(template_name_or_list),
  File "/home/ronnie/.local/share/virtualenvs/microblog-_cc4o7Cx/lib/python3.5/site-packages/jinja2/environment.py", line 869, in get_or_select_template
    return self.get_template(template_name_or_list, parent, globals)
  File "/home/ronnie/.local/share/virtualenvs/microblog-_cc4o7Cx/lib/python3.5/site-packages/jinja2/environment.py", line 830, in get_template
    return self._load_template(name, self.make_globals(globals))
  File "/home/ronnie/.local/share/virtualenvs/microblog-_cc4o7Cx/lib/python3.5/site-packages/jinja2/environment.py", line 804, in _load_template
    template = self.loader.load(self, name, globals)
  File "/home/ronnie/.local/share/virtualenvs/microblog-_cc4o7Cx/lib/python3.5/site-packages/jinja2/loaders.py", line 113, in load
    source, filename, uptodate = self.get_source(environment, name)
  File "/home/ronnie/.local/share/virtualenvs/microblog-_cc4o7Cx/lib/python3.5/site-packages/flask/templating.py", line 57, in get_source
    return self._get_source_fast(environment, template)
  File "/home/ronnie/.local/share/virtualenvs/microblog-_cc4o7Cx/lib/python3.5/site-packages/flask/templating.py", line 85, in _get_source_fast
    raise TemplateNotFound(template)
jinja2.exceptions.TemplateNotFound: email/reset_password.txt
2018-03-26 00:27:26,804 INFO: Microblog startup [in /home/ronnie/coding/microblog/app/__init__.py:45]
2018-03-26 00:27:38,236 ERROR: Exception on /reset_password_request [POST] [in /home/ronnie/.local/share/virtualenvs/microblog-_cc4o7Cx/lib/python3.5/site-packages/flask/app.py:1560]
Traceback (most recent call last):
  File "/home/ronnie/.local/share/virtualenvs/microblog-_cc4o7Cx/lib/python3.5/site-packages/flask/app.py", line 1982, in wsgi_app
    response = self.full_dispatch_request()
  File "/home/ronnie/.local/share/virtualenvs/microblog-_cc4o7Cx/lib/python3.5/site-packages/flask/app.py", line 1614, in full_dispatch_request
    rv = self.handle_user_exception(e)
  File "/home/ronnie/.local/share/virtualenvs/microblog-_cc4o7Cx/lib/python3.5/site-packages/flask/app.py", line 1517, in handle_user_exception
    reraise(exc_type, exc_value, tb)
  File "/home/ronnie/.local/share/virtualenvs/microblog-_cc4o7Cx/lib/python3.5/site-packages/flask/_compat.py", line 33, in reraise
    raise value
  File "/home/ronnie/.local/share/virtualenvs/microblog-_cc4o7Cx/lib/python3.5/site-packages/flask/app.py", line 1612, in full_dispatch_request
    rv = self.dispatch_request()
  File "/home/ronnie/.local/share/virtualenvs/microblog-_cc4o7Cx/lib/python3.5/site-packages/flask/app.py", line 1598, in dispatch_request
    return self.view_functions[rule.endpoint](**req.view_args)
  File "/home/ronnie/coding/microblog/app/routes.py", line 155, in reset_password_request
    send_password_reset_email(user)
  File "/home/ronnie/coding/microblog/app/email.py", line 20, in send_password_reset_email
    user=user, token=token))
TypeError: send_email() got an unexpected keyword argument 'recipients'
2018-03-26 00:29:42,284 INFO: Microblog startup [in /home/ronnie/coding/microblog/app/__init__.py:45]
2018-03-26 00:29:52,366 ERROR: Exception on /reset_password_request [POST] [in /home/ronnie/.local/share/virtualenvs/microblog-_cc4o7Cx/lib/python3.5/site-packages/flask/app.py:1560]
Traceback (most recent call last):
  File "/home/ronnie/.local/share/virtualenvs/microblog-_cc4o7Cx/lib/python3.5/site-packages/flask_mail.py", line 492, in send
    message.send(connection)
  File "/home/ronnie/.local/share/virtualenvs/microblog-_cc4o7Cx/lib/python3.5/site-packages/flask_mail.py", line 427, in send
    connection.send(self)
  File "/home/ronnie/.local/share/virtualenvs/microblog-_cc4o7Cx/lib/python3.5/site-packages/flask_mail.py", line 192, in send
    message.rcpt_options)
  File "/usr/lib/python3.5/smtplib.py", line 847, in sendmail
    self.ehlo_or_helo_if_needed()
  File "/usr/lib/python3.5/smtplib.py", line 599, in ehlo_or_helo_if_needed
    if not (200 <= self.ehlo()[0] <= 299):
  File "/usr/lib/python3.5/smtplib.py", line 439, in ehlo
    self.putcmd(self.ehlo_msg, name or self.local_hostname)
  File "/usr/lib/python3.5/smtplib.py", line 366, in putcmd
    self.send(str)
  File "/usr/lib/python3.5/smtplib.py", line 358, in send
    raise SMTPServerDisconnected('please run connect() first')
smtplib.SMTPServerDisconnected: please run connect() first

During handling of the above exception, another exception occurred:

Traceback (most recent call last):
  File "/home/ronnie/.local/share/virtualenvs/microblog-_cc4o7Cx/lib/python3.5/site-packages/flask/app.py", line 1982, in wsgi_app
    response = self.full_dispatch_request()
  File "/home/ronnie/.local/share/virtualenvs/microblog-_cc4o7Cx/lib/python3.5/site-packages/flask/app.py", line 1614, in full_dispatch_request
    rv = self.handle_user_exception(e)
  File "/home/ronnie/.local/share/virtualenvs/microblog-_cc4o7Cx/lib/python3.5/site-packages/flask/app.py", line 1517, in handle_user_exception
    reraise(exc_type, exc_value, tb)
  File "/home/ronnie/.local/share/virtualenvs/microblog-_cc4o7Cx/lib/python3.5/site-packages/flask/_compat.py", line 33, in reraise
    raise value
  File "/home/ronnie/.local/share/virtualenvs/microblog-_cc4o7Cx/lib/python3.5/site-packages/flask/app.py", line 1612, in full_dispatch_request
    rv = self.dispatch_request()
  File "/home/ronnie/.local/share/virtualenvs/microblog-_cc4o7Cx/lib/python3.5/site-packages/flask/app.py", line 1598, in dispatch_request
    return self.view_functions[rule.endpoint](**req.view_args)
  File "/home/ronnie/coding/microblog/app/routes.py", line 155, in reset_password_request
    send_password_reset_email(user)
  File "/home/ronnie/coding/microblog/app/email.py", line 20, in send_password_reset_email
    user=user, token=token))
  File "/home/ronnie/coding/microblog/app/email.py", line 10, in send_email
    mail.send(msg)
  File "/home/ronnie/.local/share/virtualenvs/microblog-_cc4o7Cx/lib/python3.5/site-packages/flask_mail.py", line 492, in send
    message.send(connection)
  File "/home/ronnie/.local/share/virtualenvs/microblog-_cc4o7Cx/lib/python3.5/site-packages/flask_mail.py", line 152, in __exit__
    self.host.quit()
  File "/usr/lib/python3.5/smtplib.py", line 978, in quit
    res = self.docmd("quit")
  File "/usr/lib/python3.5/smtplib.py", line 419, in docmd
    self.putcmd(cmd, args)
  File "/usr/lib/python3.5/smtplib.py", line 366, in putcmd
    self.send(str)
  File "/usr/lib/python3.5/smtplib.py", line 358, in send
    raise SMTPServerDisconnected('please run connect() first')
smtplib.SMTPServerDisconnected: please run connect() first
2018-03-26 00:32:55,355 INFO: Microblog startup [in /home/ronnie/coding/microblog/app/__init__.py:45]
